Workbook

Sheet Test Cases
A1: No. | B1: Code | C1: Group | D1: Test name | E1: What we are checking | F1: Priority | G1: Before you start | H1: Steps | I1: What should happen | J1: Can it be automated? | K1: Notes | L1: For the automation team | M1: Result | N1: Pass / Fail | O1: Tested by | P1: Date | Q1: Requires | R1: Supplier Rule | S1: Review
A2: 1 | B2: TC-SM-NAV-001 | C2: A. Getting to the seat map | D2: You can only pick seats on step 2 | E2: Seats can only be chosen after passenger details and a fare package are filled in. | F2: High | G2: See the 'Before every test' sheet. | H2: 1. Log in to Admin and go to Booking-Mid Office. 2. Pick the branch, agency and agent, search for a flight and press 'Book Flight'. 3. Look at the step names at the top before filling anything in. | I2: There are only TWO steps: '01 Passenger Info and Bundles' and '02 Ancillaries'. There is no third step. While step 2 has not been reached, there is no 'Select Seat' button to press. | J2: Yes | K2: The wizard used to have 3 steps. It changed to 2 steps on 15 Sep 2026. | Q2: Seat | S2: Approved
A3: 2 | B3: TC-SM-NAV-002 | C3: A. Getting to the seat map | D3: You cannot reach the seats without choosing a fare package | E3: A fare package must be chosen first, because it decides which seats you are allowed to take. | F3: High | G3: See the 'Before every test' sheet. | H3: 1. On step 1, fill in every box for every passenger. 2. Do NOT choose a fare package. 3. Press 'Next'. | I3: You are not allowed to move on. The message 'Bundle selection is required' appears. Step 2 is still not reached, so the seat map cannot be opened. | J3: Yes | Q3: Seat | S3: Approved
A4: 3 | B4: TC-SM-NAV-002b | C4: A. Getting to the seat map | D4: Missing passenger details and a missing fare package are both reported | E4: One kind of error must not hide the other. | F4: Medium | G4: See the 'Before every test' sheet. | H4: 1. On an empty step 1 (nothing filled in, no fare package), press 'Next'. 2. Now fill in every passenger box, still with no fare package, and press 'Next' again. | I4: First time: 'Required' appears under each empty passenger box. Second time: only 'Bundle selection is required' appears. Neither message hides the other, and step 2 is not reached either time. | J4: Yes | Q4: None | S4: Approved
A5: 4 | B5: TC-SM-NAV-003 | C5: A. Getting to the seat map | D5: 'Select Seat' opens the seat map | E5: The map that opens belongs to the flight whose button you pressed. | F5: High | G5: See the 'Before every test' sheet. | H5: 1. Reach step 2 with a fare package chosen. 2. Press 'Select Seat' for one passenger and one flight. | I5: The seat map opens full screen. Its title reads 'Seat Map - CAI -> JED - Onward' (the airports and direction of the flight you picked). You can see: the left panel, the seat chart, the colour key and the button at the bottom. | J5: Yes | L5: The map was rebuilt on 15 Sep 2026. It is now [role="dialog"] labelled by #seat-map-shell-title, with body.seat-map-shell-open. Old scripts looking for a PrimeNG p-dialog will fail. | Q5: Seat | S5: Approved
A6: 5 | B6: TC-SM-NAV-005 | C6: A. Getting to the seat map | D6: You can skip seats completely | E6: Seats are optional - the booking must still work with no seat chosen. | F6: High | G6: See the 'Before every test' sheet. | H6: 1. Open the seat map and choose nothing. 2. Look at the button at the bottom. 3. Press 'Continue without seats'. | I6: With no seat chosen the bottom button reads 'Continue without seats'. Pressing it closes the map, gives nobody a seat, leaves the price unchanged, and the booking can still be finished. | J6: Yes | Q6: Seat | S6: Approved
A7: 6 | B7: TC-SM-RND-001 | C7: B. How the map is drawn | D7: The seat total matches the seats you can see | E7: If the map draws fewer seats than it claims, seats that could be sold are hidden. | F7: High | G7: See the 'Before every test' sheet. | H7: 1. Open the seat map. 2. Read the seat total in the left panel (shown as 'SEATS 174', for example). 3. Count the seats actually drawn. | I7: The two numbers are the same. Check that they match - do NOT expect a particular number, because every aircraft is different. | J7: Yes | Q7: Seat | S7: Approved
A8: 7 | B8: TC-SM-RND-002 | C8: B. How the map is drawn | D8: Every seat has one clear state and one seat number | E8: A seat with no state, or two seats with the same number, would break the booking. | F8: High | G8: See the 'Before every test' sheet. | H8: 1. Sort every seat into one group: free / costs money / taken / not offered to this passenger / women-only / held by someone else in your booking. 2. List every row and seat drawn. 3. Check each seat's label against the row it sits in. | I8: Every seat belongs to exactly one group, and the groups added together equal the seat total in the left panel. No seat number appears twice, and no seat is missing a state. | J8: Yes | K8: The list of states changed on 15 Sep 2026. | L8: Classes: seat--free, seat--unavailable, seat--not-offered, seat--female, seat--selected-other. A seat that costs money has none of --free or --unavailable; read its price from aria-label. | Q8: Seat | S8: Approved
A9: 8 | B9: TC-SM-RND-003 | C9: B. How the map is drawn | D9: Every seat has a full description | E9: The description is the only reliable place to read a seat's price and state. | F9: High | G9: See the 'Before every test' sheet. | H9: 1. Read the description of every seat. | I9: Each description is filled in and contains: seat number, row number, which block it is in, which section, any special features, and at the end either 'Blocked' or 'available for <price>'. The seat number in the description matches the number printed on the seat. | J9: Yes | L9: Read from aria-label on each seat button. | Q9: Seat | S9: Approved
A10: 9 | B10: TC-SM-RND-005 | C10: B. How the map is drawn | D10: Cabin and section information agrees with the map | E10: A whole cabin must not go missing from the map. | F10: Medium | G10: See the 'Before every test' sheet. | H10: 1. Compare the cabins named in the colour key with the cabins the seats actually belong to. 2. Compare each seat's section name with the section it is drawn under. 3. If the aircraft has an upper level as well as a lower one, check both are drawn. | I10: Every cabin named in the colour key exists on the map, and every cabin on the map is named in the colour key. The section names agree too. On an aircraft with two cabins, both must be shown - not only Economy. On a two-level aircraft, both levels must be shown. | J10: Yes | Q10: Seat | S10: Approved
A11: 10 | B11: TC-SM-RND-006 | C11: B. How the map is drawn | D11: The flight shown on the map is the flight you chose | E11: This proves the map is not an old or leftover one from a previous search. | F11: High | G11: See the 'Before every test' sheet. | H11: 1. Write down the route, flight number, aircraft type and times from the flight you selected. 2. Compare them with the flight details in the left panel of the seat map. | I11: All the details match, including the aircraft type. | J11: Yes | Q11: Seat | S11: Approved
A12: 11 | B12: TC-SM-RND-007 | C12: B. How the map is drawn | D12: Two different flights give two different maps | E12: Catches a map that is fixed in the code or reused from an earlier flight - the worst possible fault here. | F12: High | G12: See the 'Before every test' sheet. You also need a second flight using a DIFFERENT aircraft type. | H12: 1. Go through to the seat map for flight A and write down the aircraft, seat total, rows and layout. 2. Do the same for flight B, which uses a different aircraft type. | I12: The two maps are different, and each one matches its own aircraft. Neither map is a copy of the other. | J12: Partly | K12: You need a second flight on a different aircraft type; which aircraft flies a route is decided by the airline, so this cannot always be arranged. | Q12: Seat | S12: Approved
A13: 12 | B13: TC-SM-RND-010 | C13: B. How the map is drawn | D13: Each flight in a trip gets its own map | E13: On a return trip the second flight may be a different aircraft with a different layout. | F13: High | G13: See the 'Before every test' sheet. | H13: 1. Search a return trip (or a multi-city trip). 2. Reach step 2. 3. Open the seat map for each flight. | I13: There is a separate map for each flight, each titled with its own route and direction (Onward, Return). Each map matches its own aircraft. | J13: Yes | Q13: Seat | S13: Approved
A14: 13 | B14: TC-SM-STA-002 | C14: C. Seat colours and labels | D14: A taken seat can be looked at but not booked | E14: The system refuses by greying out the button, not by showing an error. | F14: High | G14: See the 'Before every test' sheet. | H14: 1. Click any seat shown as taken. 2. Look at the box that opens and at its button. | I14: The box opens and says 'Blocked' and 'Seat 13A is blocked.' The button is there but greyed out and now reads 'Seat unavailable'. No error message pops up, the seats-chosen count does not change, and any seat you already chose stays chosen. | J14: Yes | Q14: Seat | S14: Approved
A15: 14 | B15: TC-SM-STA-004 | C15: C. Seat colours and labels | D15: Seat features use known wording | E15: If the airline sends a new kind of feature, we must notice it instead of ignoring it. | F15: Medium | G15: See the 'Before every test' sheet. | H15: 1. Collect the feature words shown on all seats. 2. Compare them with the known list. 3. Open a seat that has more than one feature. | I15: Every feature word is one of these: Window seat, Aisle seat, Leg space seat, Chargeable seat, Exit and emergency exit, Female designated seat. Check that nothing unknown appears. Do NOT expect a particular feature to be present - each flight sends its own. | J15: Yes | K15: 'Chargeable seat' was missing from the 15 Sep map but present again on 17 Sep - it depends on the flight, so its absence is not a fault. | Q15: Seat | S15: Approved
A16: 15 | B16: TC-SM-STA-005 | C16: C. Seat colours and labels | D16: Window and aisle labels match where the seat really is | E16: A wrongly labelled seat means a passenger is sold something different from what they picked. | F16: Medium | G16: See the 'Before every test' sheet. | H16: 1. For every seat marked 'Window seat', check it really is at the edge of its row. 2. For every seat marked 'Aisle seat', check it really is next to the walkway. 3. Check middle seats carry neither label. | I16: The labels match the real position, whatever the layout is (2-2, 3-3, 3-4-3 and so on). Do NOT assume seats A and F are always windows - that is only true on this one aircraft. | J16: Yes | Q16: Seat | S16: Approved
A17: 16 | B17: TC-SM-STA-006 | C17: C. Seat colours and labels | D17: Emergency exit seats are marked | E17: Every exit-seat rule depends on being able to find these seats first. | F17: Medium | G17: See the 'Before every test' sheet. | H17: 1. Find the seats marked 'Exit and emergency exit'. 2. Check they sit next to each other and what else they are marked with. | I17: Exit seats are next to each other in their row and usually also marked 'Leg space seat'. Whether they are free to book depends on the airline - do not expect them always to be available. Two kinds of passenger may never sit there: an adult who has an infant with them, and a child. (Tested in detail in group P.) | J17: Yes | Q17: Seat | S17: Approved
A18: 17 | B18: TC-SM-STA-007 | C18: C. Seat colours and labels | D18: Women-only seats are marked clearly | E18: These seats must be explained, not just silently blocked. | F18: High | G18: See the 'Before every test' sheet. | H18: 1. Find the seats marked as women-only. 2. Check their labels, their markings and the colour key. | I18: Being a women-only seat does NOT by itself mean the seat is unavailable. For a male passenger it shows as unavailable and reads 'Female designated seat, not offered for <first name>'. For a female passenger the same seat becomes available and reads 'available for <price>'. | J18: Partly | K18: Only works on a flight that actually has women-only seats - skip cleanly when it does not. | L18: Classes: seat--female (always), plus seat--unavailable and seat--not-offered only when the passenger is male. | Q18: Seat | R18: ladies-only-seats | S18: Approved
A19: 18 | B19: TC-SM-SEL-001 | C19: D. Choosing a seat | D19: One click only shows the seat - it does not book it | E19: Stops a seat being booked by accident with a single click. | F19: Critical | G19: See the 'Before every test' sheet. | H19: 1. Open the seat map (the count reads 0 of N). 2. Click one free seat. 3. Do nothing else. | I19: An information box opens for that seat. The count still reads 0 of N, the passenger card still shows no seat, and the bottom button still reads 'Continue without seats'. Nothing has been booked. | J19: Yes | Q19: Seat | S19: Approved
A20: 19 | B20: TC-SM-SEL-002 | C20: D. Choosing a seat | D20: A seat is only taken when you press the button in the box | E20: The agent must always see which seat and which passenger they are confirming. | F20: Critical | G20: See the 'Before every test' sheet. | H20: 1. Click a free seat. 2. Read the wording on the button. 3. Press it. | I20: The button reads 'Book 5A for Mohanad' - the real seat number and the passenger's real first name from step 1. After pressing: the count goes up by one, the passenger card shows the seat, its cabin and its price, and the seat changes colour to show it is taken by you. | J20: Yes | Q20: Seat | S20: Approved
A21: 20 | B21: TC-SM-SEL-003 | C21: D. Choosing a seat | D21: The seat information box is correct | E21: This box is what the agent reads before deciding. | F21: High | G21: See the 'Before every test' sheet. | H21: 1. Click a seat. 2. Compare every line in the box with the seat's own description and with the left panel. | I21: The box shows the right state, seat number, price, cabin, where the seat sits in its row, and where the row sits in its section ('Row 5 - 5th of 7 rows in Y-1'). Everything agrees with the seat's own description. | J21: Yes | Q21: Seat | S21: Approved
A22: 21 | B22: TC-SM-SEL-006 | C22: D. Choosing a seat | D22: The bottom button changes as seats are chosen | E22: It is how the agent knows whether anything is currently held. | F22: High | G22: See the 'Before every test' sheet. | H22: 1. Note the bottom button with nothing chosen. 2. Choose a seat. 3. Read the button again. | I22: The button changes in this order: 'Continue without seats' -> 'Confirm 1 of 2 seats' -> 'Confirm 2 seats'. A 'Clear all seats' button sits next to it. The total counts only passengers who can have a seat - infants are not counted. Passenger cards show ACTIVE / SELECT / SELECTED / ASSIGNED. | J22: Yes | K22: The old wording 'Confirm seat' no longer exists. | L22: Buttons: button.confirm-action and button.confirm-reset. | Q22: Seat | S22: Approved
A23: 22 | B23: TC-SM-SEL-007 | C23: D. Choosing a seat | D23: Moving a passenger to another seat frees the first seat | E23: Otherwise one passenger holds two seats and a seat is lost from sale. | F23: High | G23: See the 'Before every test' sheet. | H23: 1. Give a passenger seat X. 2. Click seat Y and book it for the same passenger. | I23: The passenger has only seat Y. Seat X goes back to free, and the count still shows one seat for that passenger, not two. | J23: Yes | Q23: Seat | S23: Approved
A24: 23 | B24: TC-SM-SEL-008 | C24: D. Choosing a seat | D24: 'Clear all seats' also removes the seat charge | E24: Money must not stay on the booking for a seat nobody has. | F24: Medium | G24: See the 'Before every test' sheet. | H24: 1. Choose a seat. 2. Press 'Clear all seats'. | I24: All seats are given up, the count goes back to 0 of N, the seats become free again, the bottom button goes back to 'Continue without seats', and any seat charge disappears from the price breakdown. | J24: Yes | Q24: Seat | S24: Approved
A25: 24 | B25: TC-SM-SEL-009 | C25: D. Choosing a seat | D25: Confirming saves the seat and closes the map | E25: This is the record the agent and the airline both rely on. | F25: Critical | G25: See the 'Before every test' sheet. | H25: 1. Choose a seat. 2. Press the bottom button ('Confirm 1 seat'). 3. Read the 'Selected seats' list on step 2. | I25: The map closes and step 2 shows 'Selected seats - 1 traveller' with a line per passenger (name / seat / price) and the right prices. The button that opened the map now reads 'Change Seats'. If the seat cost money, a 'Seat Selection' line is added to the price breakdown. The seat number in the list is exactly the seat you clicked. | J25: Yes | Q25: Seat | S25: Approved
A26: 25 | B26: TC-SM-SEL-010 | C26: D. Choosing a seat | D26: 'Change Seats' reopens the map with your choice still there | E26: Looking at your choice again must not lose it. | F26: High | G26: See the 'Before every test' sheet. | H26: 1. Confirm a seat. 2. Press 'Change Seats'. | I26: The map opens again, the seat is still chosen, the count still shows it, and the passenger card still shows it. | J26: Yes | Q26: Seat | S26: Approved
A27: 26 | B27: TC-SM-SEL-012 | C27: D. Choosing a seat | D27: A seat held by another passenger in your booking is marked | E27: Two passengers must never hold the same seat. | F27: High | G27: See the 'Before every test' sheet. You need at least 2 passengers who can have a seat. | H27: 1. Give seat X to passenger A. 2. Switch to passenger B and click seat X. | I27: Seat X is shown as held and names who has it: 'selected for <A's full name>'. Passenger B cannot take it. | J27: Yes | K27: The business said this seat shows simply as 'Blocked'. What we actually saw names the holder, which is better - check which is intended. | L27: Class: seat--selected-other. | Q27: Seat | S27: Approved
A28: 27 | B28: TC-SM-MPX-002 | C28: E. More than one passenger or flight | D28: The seat goes to the passenger who is selected | E28: Stops a seat being given to the wrong passenger. | F28: Critical | G28: See the 'Before every test' sheet. You need at least 2 passengers. | H28: 1. With several passengers, note which card is selected and book a seat. 2. Click a different passenger's card. 3. Book a second seat. | I28: The first seat goes to the passenger who was selected, and the button named that passenger. The others still have no seat. After switching, the second seat goes to the newly selected passenger, the first passenger keeps theirs, and the count reads 2 of N. | J28: Yes | Q28: Seat | S28: Approved
A29: 28 | B29: TC-SM-MPX-004 | C29: E. More than one passenger or flight | D29: Two passengers cannot have the same seat | E29: The airline would reject a booking with one seat given to two people. | F29: Critical | G29: See the 'Before every test' sheet. You need at least 2 passengers. | H29: 1. Give seat X to passenger 1. 2. Select passenger 2 and try to book seat X. | I29: Passenger 2 cannot take seat X. It is shown as held, and it names who has it: 'selected for <full name>'. One seat must never be held by two passengers. | J29: Yes | K29: The business answered 'Blocked' on 17 Sep, but what we saw on 15 Sep also names the holder. Treat the named version as correct and report a plain 'Blocked' with no name. | L29: Class: seat--selected-other. | Q29: Seat | S29: Approved
A30: 29 | B30: TC-SM-MPX-006 | C30: E. More than one passenger or flight | D30: Seats on one flight do not affect the other flight | E30: Each flight of a return trip is seated separately. | F30: High | G30: See the 'Before every test' sheet. You need a return trip. | H30: 1. On a return trip, choose seats for the outbound flight and confirm. 2. Open the map for the return flight. 3. Choose a seat on the return flight. | I30: The return map starts empty - it does not copy the outbound seats. Choosing a return seat does not disturb the outbound one, and the summary shows each flight separately. | J30: Yes | Q30: Seat | S30: Approved
A31: 30 | B31: TC-SM-MPX-007 | C31: E. More than one passenger or flight | D31: Some passengers can have seats and others none | E31: Seats are optional for each passenger. | F31: Medium | G31: See the 'Before every test' sheet. You need 2 passengers. | H31: 1. With 2 passengers, give a seat to one only. 2. Confirm. | I31: Confirming is allowed with 1 of 2 chosen. The summary lists the one seated passenger, and the booking can still be finished. | J31: Yes | Q31: Seat | S31: Approved
A32: 31 | B32: TC-SM-PRC-001 | C32: F. Prices | D32: A seat included in the fare package costs nothing | E32: The agency must not pay twice for something the package already covers. | F32: Critical | G32: See the 'Before every test' sheet. The fare package must be 'Plus' (it says 'Seat selection: All seats'). Under 'Value' this test would correctly fail, because those seats are paid. | H32: 1. Choose the 'Plus' package. 2. Write down the amount to pay. 3. Choose a seat and confirm. | I32: The left panel reads 'No seat charges - Free', the seat's price reads 'Free', and the amount to pay does not change. The summary line for the seat shows a price of zero. | J32: Yes | Q32: Bundle + Seat | S32: Approved
A33: 32 | B33: TC-SM-PRC-002 | C33: F. Prices | D33: A seat marked 'Chargeable seat' must always have a price | E33: A seat described as chargeable must never be shown as free, whatever fare package is chosen. | F33: High | G33: See the 'Before every test' sheet. You need a flight that actually shows the words 'Chargeable seat' - check this first, because not every flight sends them. | H33: 1. Choose the 'Plus' package (it says 'Seat selection: All seats') and find a seat marked 'Chargeable seat'. 2. Write down the words on the seat and its price. 3. On the SAME flight, change to the 'Value' package and look at a seat marked the same way. 4. Check the amount to pay before and after booking such a seat. | I33: A seat marked 'Chargeable seat' ALWAYS has a price, under every fare package. If it shows 'Free', that is a FAULT - report it. Known fault seen on 09 Sep 2026: under 'Plus', seat 5A read 'Chargeable seat' and 'available for Free', the amount to pay did not change, and the summary showed a price of zero. Under 'Value' the behaviour was correct: seat 6C read 'Chargeable seat' with a price of EGP 642. | J33: Yes | K33: CORRECTED 17 Sep 2026. The business first said a free chargeable seat was acceptable, then ruled that a chargeable seat must always be paid. This test now looks for a fault instead of accepting the behaviour. 27 Sep 2026 (run-006): reproduced on flynas KSA, XY584. Confirmed as a bug by the business. | M33: Under 'Plus', all 36 seats marked 'Chargeable seat' showed 'available for Free' (e.g. 5A); the total did not change. Under 'Value' they were priced correctly. | N33: Fail | O33: Claude (run-006), for Mohanad Dawood | P33: 27 Sep 2026 | Q33: Seat | S33: Approved
A34: 33 | B34: TC-SM-PRC-003 | C34: F. Prices | D34: A paid seat is added as its own line in the price | E34: The agency must be able to see exactly what the seat cost. | F34: Critical | G34: See the 'Before every test' sheet. Use the 'Value' package, which does not include seat choice. | H34: 1. Choose the 'Value' package. 2. Open the seat map. 3. Choose a seat that has a price and confirm it. | I34: A 'Seat Selection' line appears in the price breakdown, separate from the fare package line. The amount to pay goes up by exactly the price of the seats chosen. Check the sum is right - do not expect a fixed amount, prices change per flight. | J34: Yes | K34: Was impossible to test before 15 Sep 2026, because no paid seat had ever been seen. | Q34: Seat | S34: Approved
A35: 34 | B35: TC-SM-PRC-003b | C35: F. Prices | D35: One aircraft can have several seat prices at once | E35: A price belongs to a seat and its section, not to the whole flight. | F35: High | G35: See the 'Before every test' sheet. Use the 'Value' package. | H35: 1. Group the seats by the price shown on each one. 2. Compare the groups with the price written above each section and with the colour key. | I35: Several different prices can appear on one aircraft, and that is correct. The price written above a section matches the seats in it ('from EGP 642', 'Free - EGP 642', 'All seats free'). Free and paid seats can be mixed inside ONE section, so never say 'rows 5 to 10 cost X' - a price belongs to a seat, not a row. | J35: Yes | K35: Seen on 15 Sep: Free / 422.91 / 1,097.91. Seen on 17 Sep: section Y-1 'from EGP 642', section Y-2 'Free - EGP 642'. | Q35: Seat | S35: Approved
A36: 35 | B36: TC-SM-PRC-004 | C36: F. Prices | D36: The price breakdown adds up | E36: This is the amount the agency wallet is actually charged. | F36: High | G36: See the 'Before every test' sheet. | H36: 1. Write down the base fare, the extras and each line under it, the taxes, the total and the amount to pay. 2. Add them up. | I36: The extras total equals the fare package + meal + baggage + seat. The amount to pay equals the base fare plus that total. The 'Seat Selection' line only appears once a PAID seat is confirmed. Check the sums, not the exact amounts. | J36: Yes | K36: Checked on 15 Sep 2026: 1,800 + 1,295.82 = 3,095.82, total 10,413.82 EGP. | Q36: Seat | S36: Approved
A37: 36 | B37: TC-SM-BND-002 | C37: G. Fare packages | D37: Changing the fare package recalculates the seats | E37: A seat that stays free after downgrading the package is money lost. | F37: Critical | G37: See the 'Before every test' sheet. | H37: 1. Choose the 'Plus' package on step 1, open the seat map and confirm a free seat. 2. Go back to step 1 and change the package to 'Value'. 3. Return to step 2, open the map again and read the prices and the total. | I37: The seat must either be given a price or be released. It must NOT stay free. The total must agree with the new price. This is the most important test in the suite - a free seat surviving the downgrade is direct money lost. | J37: Partly | K37: 27 Sep 2026 (run-006): business confirms this is a feature, not a defect - bundle change clears ancillaries, it does not recalculate them. Not retried; the stuck-wizard observation from the earlier 16 attempts stands as a separate item. | M37: The case's own premise was wrong. Per business decision, changing the fare package is not meant to recalculate the seats - it clears the ancillaries (seats, meals, bags) so the agent re-selects them under the new bundle. This run's attempts to observe a downgrade never reached that point: after downgrading Plus -> Value, advancing to step 2 failed twice with a sold-out ssr-quote error and the wizard stayed on step 1 with no visible message - a separate, still-open observation (tied to V6-12), not a failure of this case. | N37: Pass | O37: Claude (run-006), for Mohanad Dawood | P37: 27 Sep 2026 | Q37: Bundle + Seat | S37: Approved
A38: 37 | B38: TC-SM-BND-003 | C38: G. Fare packages | D38: Each flight uses its own fare package | E38: On a trip with two flights, each one is priced on its own terms. | F38: Medium | G38: See the 'Before every test' sheet. You need a trip with more than one flight. | H38: 1. Choose a different package for each flight - one that includes seats, one that does not. 2. Open the seat map for each flight. | I38: Each flight's seats are priced by ITS OWN package, independently of the other flight. | J38: Yes | Q38: Bundle | S38: Approved
A39: 38 | B39: TC-SM-BND-004 | C39: G. Fare packages | D39: Fare package names are never blank or repeated | E39: The agent must be able to tell the packages apart and get the one they picked. | F39: Medium | G39: See the 'Before every test' sheet. | H39: 1. Look at the list of fare packages offered. 2. Choose each one in turn and open the seat map. | I39: The Economy fare offers four clearly different names: 'Plus', 'Light Super Flex', 'Value', 'Value Flex'. No name is blank and no name appears twice. Each one can be chosen and leads to a working seat map. If a blank or repeated name comes back, report it - this used to happen and was fixed. | J39: Yes | K39: This test used to record the fault. Since 15 Sep 2026 it guards against the fault returning. | Q39: Bundle | S39: Approved
A40: 39 | B40: TC-SM-BND-005 | C40: G. Fare packages | D40: What the package promises about seats is what you get | E40: Promising seats the package does not give is mis-selling. | F40: High | G40: See the 'Before every test' sheet. Note the 'Seat selection: ...' line of the package you choose. | H40: 1. Read the 'Seat selection: ...' line in the package details. 2. Open the seat map and check which seats you can actually choose. | I40: What the package says matches what the map gives. Seen so far: 'All seats' gave 161 of 174 seats, all free. 'Premium' gave 4 of 174, free. 'Standard' gave 156 of 174, with 96 free and 60 paid. Check that the wording and the map agree - never expect these exact counts. | J40: Yes | Q40: Bundle + Seat | S40: Approved
...

Sheet Before every test
A1: Before every test - read this once
A4: Where | B4: Admin panel at http://192.168.1.70 - Booking-Mid Office - Flight Search.
A5: Who | B5: Log in as the admin user, then choose the branch, the agency and the agent before searching. Nothing works until all three are chosen.
A6: What to search | B6: Branch BRN298, Cairo (CAI) to Jeddah (JED), 1 adult + 1 child + 1 infant, unless a test says otherwise. The travel date must be in the future - update it when it passes.
A7: NEVER press 'Book' | B7: Pressing 'Book' creates a REAL booking and takes real money from the agency wallet. Stop at the payment screen, or use 'Save Quote'.
A8: Two steps | B8: Step 1 is 'Passenger Info and Bundles' - passenger details and the fare package. Step 2 is 'Ancillaries' - meals, bags and seats. There is no third step.
A10: Words used in this sheet
A11: fare package (bundle) | B11: The fare option you pick on step 1, such as 'Plus' or 'Value'. It decides which seats you get and whether they cost extra.
A12: extras (ancillaries) | B12: Meals, extra bags and seats - everything on step 2.
A13: left panel | B13: The strip down the left of the seat map showing the flight, the seat total and the passenger cards.
A14: seat chart | B14: The drawing of the aircraft with all the seats.
A15: colour key | B15: The box headed 'What the plan shows' that explains the seat colours.
A16: section | B16: A named block of rows, such as Y-1 or Y-2. Each section has its own price written above it.
A17: seats-chosen count | B17: The '0 of 2' counter showing how many passengers have a seat so far. Infants are never counted.
A19: Important rule for writing tests
A20: Never fix a row or seat number | B20: Every flight uses a different aircraft, so the rows, seats, totals and prices change. Always find a seat by what it is marked with, and check that numbers agree with each other - never that they equal a particular figure.
A21: Say which cabin and package | B21: The same flight gives a completely different map in Economy and Business, and a different one again for each fare package. A test that does not say which it used cannot be repeated.
A22: Staging warning | B22: The airline connection in use is the test one ('Fly Nas NDC EGY Staging'). It reports cabins wrongly. Prices, cabins and seat availability seen here must be checked again on the live connection.
A24: Every booking run needs FRESH passenger names and document numbers.
A25: The system refuses a second booking for a passenger whose name, date of birth and document already have one. It returns a clear message that is NEVER shown on screen, so the booking simply appears to do nothing. This is not a seat-map test - it is a constraint on how the tests are run.

Sheet Questions for the business
A1: Questions for the business
A3: Most questions were answered on 17 Sep 2026. Only the ones still open need a decision. An unanswered question does not stop a test running - run it, write down what happened, and do not mark it failed.
A5: Question | B5: Answer / status | C5: What it means for testing
A6: Is a seat marked 'Chargeable seat' but priced Free a mistake? | B6: ANSWERED, THEN CORRECTED - a chargeable seat must ALWAYS be paid. It can never be free. | C6: Test 32 now reports a fault if such a seat shows as free. The free seat seen under 'Plus' on 09 Sep is a defect.
A7: What happens when the time limit runs out? | B7: ANSWERED - the agent is sent back to the flight search page. The limit is 60 minutes for testing and 15 minutes when live. | C7: Tests 48 and 52. Do not write 60 minutes into any test; re-run both before go-live.
A8: Is a seat held as soon as it is chosen? | B8: ANSWERED - no. Two agents can both choose it. The clash is settled at booking: one succeeds, the other is told the seat is taken. | C8: Test 51 can only be finished by really pressing 'Book', which needs approval.
A9: Why does a Business fare show every section as Economy? | B9: ANSWERED - it is a staging data problem, not a system fault. It does not happen on the live connection. | C9: Test 60 waits for the live connection. Do not report the wrong cabin name as a fault.
A10: Should the agent be able to tell WHY a seat cannot be chosen? | B10: STILL OPEN - needs a decision. | C10: A seat can be unavailable for four reasons but the screen shows only two messages. See the table below.
A11: Is the price change between search and booking expected? | B11: ANSWERED - yes, known behaviour. It happens when an infant is in the party. | C11: Test 66 uses an infant to make it happen on purpose.
A12: Are children under the same seat rules as adults? | B12: ANSWERED - yes, for both exit seats and women-only seats. | C12: Tests 45 and 74-79.
A13: Which passengers cannot sit in an exit seat? | B13: ANSWERED - two kinds only: an adult who has an infant with them, and a child. | C13: Tests 74 to 79. Still to check: at which point the system stops them.
A14: How is a seat taken by another passenger in the same booking shown? | B14: ANSWERED as 'Blocked' - but what we actually saw also NAMES the passenger holding it. | C14: Tests 26 and 28 expect the named version. Please confirm which is intended.
A15: A server error is shown as 'No Flights Found'. Is that acceptable? | B15: ACCEPTED - known behaviour, will not be reported as a fault. | C15: Test 70 stays as a background check only.
A16: The airline connection in use is the test one. Does that matter? | B16: STILL OPEN - and it does matter: it reports cabins wrongly. | C16: Every price, cabin and seat figure must be checked again on the live connection.
A19: Why a seat cannot be chosen - four reasons, two messages
A20: What is really true | B20: What the agent sees
A21: This part of the aircraft is not in your fare | B21: Not offered
A22: This seat is kept for women and your passenger is male | B22: Not offered
A23: Somebody else has this seat | B23: Blocked
A24: Another passenger in YOUR booking has this seat | B24: Shown as held, and it names them

Sheet Summary
A1: Summary
A3: Tests in this sheet | B3: 79
A5: By priority | C5: Passed
A6: Critical | B6: 15 | C6: =COUNTIFS('Test Cases'!$F$2:$F$80,$A6,'Test Cases'!$N$2:$N$80,"Pass")
A7: High | B7: 41 | C7: =COUNTIFS('Test Cases'!$F$2:$F$80,$A7,'Test Cases'!$N$2:$N$80,"Pass")
A8: Medium | B8: 20 | C8: =COUNTIFS('Test Cases'!$F$2:$F$80,$A8,'Test Cases'!$N$2:$N$80,"Pass")
A9: Low | B9: 3 | C9: =COUNTIFS('Test Cases'!$F$2:$F$80,$A9,'Test Cases'!$N$2:$N$80,"Pass")
A11: Can it be automated?
A12: Yes | B12: 67
A13: Partly | B13: 10
A14: No | B14: 2
A16: By group
A17: A. Getting to the seat map | B17: 5 | C17: =COUNTIFS('Test Cases'!$C$2:$C$80,$A17,'Test Cases'!$N$2:$N$80,"Pass")
A18: B. How the map is drawn | B18: 7 | C18: =COUNTIFS('Test Cases'!$C$2:$C$80,$A18,'Test Cases'!$N$2:$N$80,"Pass")
A19: C. Seat colours and labels | B19: 5 | C19: =COUNTIFS('Test Cases'!$C$2:$C$80,$A19,'Test Cases'!$N$2:$N$80,"Pass")
A20: D. Choosing a seat | B20: 9 | C20: =COUNTIFS('Test Cases'!$C$2:$C$80,$A20,'Test Cases'!$N$2:$N$80,"Pass")
A21: E. More than one passenger or flight | B21: 4 | C21: =COUNTIFS('Test Cases'!$C$2:$C$80,$A21,'Test Cases'!$N$2:$N$80,"Pass")
A22: F. Prices | B22: 5 | C22: =COUNTIFS('Test Cases'!$C$2:$C$80,$A22,'Test Cases'!$N$2:$N$80,"Pass")
A23: G. Fare packages | B23: 4 | C23: =COUNTIFS('Test Cases'!$C$2:$C$80,$A23,'Test Cases'!$N$2:$N$80,"Pass")
A24: H. Women-only seats | B24: 6 | C24: =COUNTIFS('Test Cases'!$C$2:$C$80,$A24,'Test Cases'!$N$2:$N$80,"Pass")
A25: I. Keeping the choice | B25: 4 | C25: =COUNTIFS('Test Cases'!$C$2:$C$80,$A25,'Test Cases'!$N$2:$N$80,"Pass")
A26: J. Errors and clashes | B26: 3 | C26: =COUNTIFS('Test Cases'!$C$2:$C$80,$A26,'Test Cases'!$N$2:$N$80,"Pass")
A27: K. Small screens and screen readers | B27: 2 | C27: =COUNTIFS('Test Cases'!$C$2:$C$80,$A27,'Test Cases'!$N$2:$N$80,"Pass")
A28: L. Economy and Business | B28: 6 | C28: =COUNTIFS('Test Cases'!$C$2:$C$80,$A28,'Test Cases'!$N$2:$N$80,"Pass")
... A32: P. Emergency exit seats | B32: 6 | C32: =COUNTIFS('Test Cases'!$C$2:$C$80,$A32,'Test Cases'!$N$2:$N$80,"Pass")
A34: Passed so far | B34: =COUNTIF('Test Cases'!$N$2:$N$80,"Pass")
A35: Failed so far | B35: =COUNTIF('Test Cases'!$N$2:$N$80,"Fail")
